<?xml version="1.0" encoding="utf-8"?>
<!-- =================================================================================== -->
<!-- |    This document was autogenerated by xacro from abi.xacro                      | -->
<!-- |    EDITING THIS FILE BY HAND IS NOT RECOMMENDED                                 | -->
<!-- =================================================================================== -->
<robot name="abi">
  <material name="silver">
    <color rgba="0.700 0.700 0.700 1.000"/>
  </material>
  <transmission name="r_hip_roll_joint_tran">
    <type>transmission_interface/SimpleTransmission</type>
    <joint name="r_hip_roll_joint">
      <hardwareInterface>hardware_interface/EffortJointInterface</hardwareInterface>
    </joint>
    <actuator name="r_hip_roll_joint_actr">
      <hardwareInterface>hardware_interface/EffortJointInterface</hardwareInterface>
      <mechanicalReduction>1</mechanicalReduction>
    </actuator>
  </transmission>
  <transmission name="l_hip_roll_joint_tran">
    <type>transmission_interface/SimpleTransmission</type>
    <joint name="l_hip_roll_joint">
      <hardwareInterface>hardware_interface/EffortJointInterface</hardwareInterface>
    </joint>
    <actuator name="l_hip_roll_joint_actr">
      <hardwareInterface>hardware_interface/EffortJointInterface</hardwareInterface>
      <mechanicalReduction>1</mechanicalReduction>
    </actuator>
  </transmission>
  <transmission name="r_hip_yaw_joint_tran">
    <type>transmission_interface/SimpleTransmission</type>
    <joint name="r_hip_yaw_joint">
      <hardwareInterface>hardware_interface/EffortJointInterface</hardwareInterface>
    </joint>
    <actuator name="r_hip_yaw_joint_actr">
      <hardwareInterface>hardware_interface/EffortJointInterface</hardwareInterface>
      <mechanicalReduction>1</mechanicalReduction>
    </actuator>
  </transmission>
  <transmission name="l_hip_yaw_joint_tran">
    <type>transmission_interface/SimpleTransmission</type>
    <joint name="l_hip_yaw_joint">
      <hardwareInterface>hardware_interface/EffortJointInterface</hardwareInterface>
    </joint>
    <actuator name="l_hip_yaw_joint_actr">
      <hardwareInterface>hardware_interface/EffortJointInterface</hardwareInterface>
      <mechanicalReduction>1</mechanicalReduction>
    </actuator>
  </transmission>
  <transmission name="l_hip_pitch_joint_tran">
    <type>transmission_interface/SimpleTransmission</type>
    <joint name="l_hip_pitch_joint">
      <hardwareInterface>hardware_interface/EffortJointInterface</hardwareInterface>
    </joint>
    <actuator name="l_hip_pitch_joint_actr">
      <hardwareInterface>hardware_interface/EffortJointInterface</hardwareInterface>
      <mechanicalReduction>1</mechanicalReduction>
    </actuator>
  </transmission>
  <transmission name="r_hip_pitch_joint_tran">
    <type>transmission_interface/SimpleTransmission</type>
    <joint name="r_hip_pitch_joint">
      <hardwareInterface>hardware_interface/EffortJointInterface</hardwareInterface>
    </joint>
    <actuator name="r_hip_pitch_joint_actr">
      <hardwareInterface>hardware_interface/EffortJointInterface</hardwareInterface>
      <mechanicalReduction>1</mechanicalReduction>
    </actuator>
  </transmission>
  <transmission name="r_knee_pitch_joint_tran">
    <type>transmission_interface/SimpleTransmission</type>
    <joint name="r_knee_pitch_joint">
      <hardwareInterface>hardware_interface/EffortJointInterface</hardwareInterface>
    </joint>
    <actuator name="r_knee_pitch_joint_actr">
      <hardwareInterface>hardware_interface/EffortJointInterface</hardwareInterface>
      <mechanicalReduction>1</mechanicalReduction>
    </actuator>
  </transmission>
  <transmission name="l_knee_pitch_joint_tran">
    <type>transmission_interface/SimpleTransmission</type>
    <joint name="l_knee_pitch_joint">
      <hardwareInterface>hardware_interface/EffortJointInterface</hardwareInterface>
    </joint>
    <actuator name="l_knee_pitch_joint_actr">
      <hardwareInterface>hardware_interface/EffortJointInterface</hardwareInterface>
      <mechanicalReduction>1</mechanicalReduction>
    </actuator>
  </transmission>
  <transmission name="r_ankle_pitch_joint_tran">
    <type>transmission_interface/SimpleTransmission</type>
    <joint name="r_ankle_pitch_joint">
      <hardwareInterface>hardware_interface/EffortJointInterface</hardwareInterface>
    </joint>
    <actuator name="r_ankle_pitch_joint_actr">
      <hardwareInterface>hardware_interface/EffortJointInterface</hardwareInterface>
      <mechanicalReduction>1</mechanicalReduction>
    </actuator>
  </transmission>
  <transmission name="l_ankle_pitch_joint_tran">
    <type>transmission_interface/SimpleTransmission</type>
    <joint name="l_ankle_pitch_joint">
      <hardwareInterface>hardware_interface/EffortJointInterface</hardwareInterface>
    </joint>
    <actuator name="l_ankle_pitch_joint_actr">
      <hardwareInterface>hardware_interface/EffortJointInterface</hardwareInterface>
      <mechanicalReduction>1</mechanicalReduction>
    </actuator>
  </transmission>
  <transmission name="l_ankle_roll_joint_tran">
    <type>transmission_interface/SimpleTransmission</type>
    <joint name="l_ankle_roll_joint">
      <hardwareInterface>hardware_interface/EffortJointInterface</hardwareInterface>
    </joint>
    <actuator name="l_ankle_roll_joint_actr">
      <hardwareInterface>hardware_interface/EffortJointInterface</hardwareInterface>
      <mechanicalReduction>1</mechanicalReduction>
    </actuator>
  </transmission>
  <transmission name="r_ankle_roll_joint_tran">
    <type>transmission_interface/SimpleTransmission</type>
    <joint name="r_ankle_roll_joint">
      <hardwareInterface>hardware_interface/EffortJointInterface</hardwareInterface>
    </joint>
    <actuator name="r_ankle_roll_joint_actr">
      <hardwareInterface>hardware_interface/EffortJointInterface</hardwareInterface>
      <mechanicalReduction>1</mechanicalReduction>
    </actuator>
  </transmission>
  <gazebo>
    <plugin filename="libgazebo_ros_control.so" name="control"/>
  </gazebo>
  <gazebo>
    <plugin filename="libgazebo_ros_p3d.so" name="ground_truth">
      <frameName>map</frameName>
      <bodyName>base_link</bodyName>
      <topicName>/abi/odom</topicName>
      <updateRate>100.0</updateRate>
    </plugin>
  </gazebo>
  <!-- imu sensor -->
  <gazebo reference="imu_link">
    <gravity>true</gravity>
    <sensor name="imu_sensor" type="imu">
      <always_on>true</always_on>
      <update_rate>100</update_rate>
      <visualize>true</visualize>
      <topic>/abi/sensor/imu</topic>
      <plugin filename="libgazebo_ros_imu_sensor.so" name="imu_plugin">
        <topicName>abi/sensor/imu</topicName>
        <bodyName>imu_link</bodyName>
        <updateRateHZ>10.0</updateRateHZ>
        <gaussianNoise>0.0</gaussianNoise>
        <xyzOffset>0 0 0</xyzOffset>
        <rpyOffset>0 0 0</rpyOffset>
        <frameName>imu_link</frameName>
      </plugin>
      <pose>0 0 0 0 0 0</pose>
    </sensor>
  </gazebo>
  <!-- World -->
  <gazebo reference="world"/>
  <!-- Map -->
  <gazebo reference="map"/>
  <!-- Base -->
  <gazebo reference="base_link"/>
  <!-- IMU -->
  <gazebo reference="imu_link"/>
  <gazebo reference="base_link">
    <material>Gazebo/Silver</material>
    <mu1>0.2</mu1>
    <mu2>0.2</mu2>
    <selfCollide>true</selfCollide>
    <gravity>true</gravity>
  </gazebo>
  <gazebo reference="r_hip_roll_link_1">
    <material>Gazebo/Silver</material>
    <mu1>0.2</mu1>
    <mu2>0.2</mu2>
    <selfCollide>true</selfCollide>
  </gazebo>
  <gazebo reference="l_hip_roll_link__1__1">
    <material>Gazebo/Silver</material>
    <mu1>0.2</mu1>
    <mu2>0.2</mu2>
    <selfCollide>true</selfCollide>
  </gazebo>
  <gazebo reference="r_hip_yaw_link_1">
    <material>Gazebo/Silver</material>
    <mu1>0.2</mu1>
    <mu2>0.2</mu2>
    <selfCollide>true</selfCollide>
  </gazebo>
  <gazebo reference="l_hip_yaw_link_1">
    <material>Gazebo/Silver</material>
    <mu1>0.2</mu1>
    <mu2>0.2</mu2>
    <selfCollide>true</selfCollide>
  </gazebo>
  <gazebo reference="l_hip_pitch_link__1__1">
    <material>Gazebo/Silver</material>
    <mu1>0.2</mu1>
    <mu2>0.2</mu2>
    <selfCollide>true</selfCollide>
  </gazebo>
  <gazebo reference="r_hip_pitch_link__1__1">
    <material>Gazebo/Silver</material>
    <mu1>0.2</mu1>
    <mu2>0.2</mu2>
    <selfCollide>true</selfCollide>
  </gazebo>
  <gazebo reference="r_knee_pitch_link__1__1">
    <material>Gazebo/Silver</material>
    <mu1>0.2</mu1>
    <mu2>0.2</mu2>
    <selfCollide>true</selfCollide>
  </gazebo>
  <gazebo reference="l_knee_pitch_link__1__1">
    <material>Gazebo/Silver</material>
    <mu1>0.2</mu1>
    <mu2>0.2</mu2>
    <selfCollide>true</selfCollide>
  </gazebo>
  <gazebo reference="r_ankle_pitch_link__1__1">
    <material>Gazebo/Silver</material>
    <mu1>0.2</mu1>
    <mu2>0.2</mu2>
    <selfCollide>true</selfCollide>
  </gazebo>
  <gazebo reference="l_ankle_pitch_link__1__1">
    <material>Gazebo/Silver</material>
    <mu1>0.2</mu1>
    <mu2>0.2</mu2>
    <selfCollide>true</selfCollide>
  </gazebo>
  <gazebo reference="l_ankle_roll_link__1__1">
    <kp>100000.0</kp>
    <kd>100.0</kd>
    <mu1>1000</mu1>
    <mu2>1000</mu2>
    <!--<maxContacts>30</maxContacts>-->
    <fdir1>1 1 0</fdir1>
    <maxVel>1.0</maxVel>
    <minDepth>0.0001</minDepth>
    <material>Gazebo/Blue</material>
  </gazebo>
  <gazebo reference="r_ankle_roll_link__1__1">
    <kp>100000.0</kp>
    <kd>100.0</kd>
    <mu1>1000</mu1>
    <mu2>1000</mu2>
    <!--<maxContacts>30</maxContacts>-->
    <fdir1>1 1 0</fdir1>
    <maxVel>1.0</maxVel>
    <minDepth>0.0001</minDepth>
    <material>Gazebo/Blue</material>
  </gazebo>
  <link name="base_link"/>
  <joint name="base_fixed" type="fixed">
    <origin rpy="0 0 0" xyz="0 0 0"/>
    <parent link="base_link"/>
    <child link="base_footprint"/>
  </joint>
  <!-- base_link -->
  <link name="base_footprint">
    <inertial>
      <origin rpy="0 0 0" xyz="0.11526276092885947 0.0685580229960114 0.6049745000867683"/>
      <mass value="0.14056247189322119"/>
      <inertia ixx="5.4e-05" ixy="-0.0" ixz="-0.0" iyy="0.000105" iyz="0.0" izz="8.7e-05"/>
    </inertial>
    <visual>
      <origin rpy="0 0 0" xyz="0 0 0"/>
      <geometry>
        <mesh filename="package://abi_description/meshes/base_link.stl" scale="0.001 0.001 0.001"/>
      </geometry>
      <material name="silver"/>
    </visual>
    <collision>
      <origin rpy="0 0 0" xyz="0 0 0"/>
      <geometry>
        <mesh filename="package://abi_description/meshes/base_link.stl" scale="0.001 0.001 0.001"/>
      </geometry>
    </collision>
  </link>
  <!-- imu joint -->
  <joint name="imu_fixed" type="fixed">
    <origin rpy="0 0 0" xyz="0.0 0 0.63"/>
    <parent link="base_footprint"/>
    <child link="imu_link"/>
  </joint>
  <link name="imu_link"/>
  <link name="r_hip_roll_link_1">
    <inertial>
      <origin rpy="0 0 0" xyz="-0.0455984855206972 0.019492903051518427 0.0001803076313984242"/>
      <mass value="0.07674208804659018"/>
      <inertia ixx="2.5e-05" ixy="-1e-06" ixz="0.0" iyy="2.7e-05" iyz="0.0" izz="3.4e-05"/>
    </inertial>
    <visual>
      <origin rpy="0 0 0" xyz="-0.095665 -0.048506 -0.588984"/>
      <geometry>
        <mesh filename="package://abi_description/meshes/r_hip_roll_link_1.stl" scale="0.001 0.001 0.001"/>
      </geometry>
      <material name="silver"/>
    </visual>
    <collision>
      <origin rpy="0 0 0" xyz="-0.095665 -0.048506 -0.588984"/>
      <geometry>
        <mesh filename="package://abi_description/meshes/r_hip_roll_link_1.stl" scale="0.001 0.001 0.001"/>
      </geometry>
    </collision>
  </link>
  <link name="l_hip_roll_link__1__1">
    <inertial>
      <origin rpy="0 0 0" xyz="0.04556544500909446 0.019492904189384326 0.0001803453115176712"/>
      <mass value="0.11897998147005992"/>
      <inertia ixx="3.9e-05" ixy="1e-06" ixz="-0.0" iyy="4.2e-05" iyz="0.0" izz="5.3e-05"/>
    </inertial>
    <visual>
      <origin rpy="0 0 0" xyz="-0.134824 -0.048506 -0.588984"/>
      <geometry>
        <mesh filename="package://abi_description/meshes/l_hip_roll_link__1__1.stl" scale="0.001 0.001 0.001"/>
      </geometry>
      <material name="silver"/>
    </visual>
    <collision>
      <origin rpy="0 0 0" xyz="-0.134824 -0.048506 -0.588984"/>
      <geometry>
        <mesh filename="package://abi_description/meshes/l_hip_roll_link__1__1.stl" scale="0.001 0.001 0.001"/>
      </geometry>
    </collision>
  </link>
  <link name="r_hip_yaw_link_1">
    <inertial>
      <origin rpy="0 0 0" xyz="0.00010070088882587619 0.014546186099299342 -0.02316980321419737"/>
      <mass value="0.15342441399034815"/>
      <inertia ixx="5.4e-05" ixy="-1e-06" ixz="0.0" iyy="3.9e-05" iyz="1e-06" izz="6.4e-05"/>
    </inertial>
    <visual>
      <origin rpy="0 0 0" xyz="-0.043165 -0.056556 -0.569234"/>
      <geometry>
        <mesh filename="package://abi_description/meshes/r_hip_yaw_link_1.stl" scale="0.001 0.001 0.001"/>
      </geometry>
      <material name="silver"/>
    </visual>
    <collision>
      <origin rpy="0 0 0" xyz="-0.043165 -0.056556 -0.569234"/>
      <geometry>
        <mesh filename="package://abi_description/meshes/r_hip_yaw_link_1.stl" scale="0.001 0.001 0.001"/>
      </geometry>
    </collision>
  </link>
  <link name="l_hip_yaw_link_1">
    <inertial>
      <origin rpy="0 0 0" xyz="0.00010068460047474304 0.014546186099300383 -0.023169803214203477"/>
      <mass value="0.15342441399034815"/>
      <inertia ixx="5.4e-05" ixy="-1e-06" ixz="0.0" iyy="3.9e-05" iyz="1e-06" izz="6.4e-05"/>
    </inertial>
    <visual>
      <origin rpy="0 0 0" xyz="-0.187324 -0.056556 -0.569234"/>
      <geometry>
        <mesh filename="package://abi_description/meshes/l_hip_yaw_link_1.stl" scale="0.001 0.001 0.001"/>
      </geometry>
      <material name="silver"/>
    </visual>
    <collision>
      <origin rpy="0 0 0" xyz="-0.187324 -0.056556 -0.569234"/>
      <geometry>
        <mesh filename="package://abi_description/meshes/l_hip_yaw_link_1.stl" scale="0.001 0.001 0.001"/>
      </geometry>
    </collision>
  </link>
  <link name="l_hip_pitch_link__1__1">
    <inertial>
      <origin rpy="0 0 0" xyz="0.027708594764509903 0.006582375867326427 -0.15609272532253105"/>
      <mass value="0.24713382283834445"/>
      <inertia ixx="0.001846" ixy="3e-06" ixz="7.5e-05" iyy="0.001908" iyz="-6.3e-05" izz="0.000133"/>
    </inertial>
    <visual>
      <origin rpy="0 0 0" xyz="-0.163824 -0.056556 -0.545234"/>
      <geometry>
        <mesh filename="package://abi_description/meshes/l_hip_pitch_link__1__1.stl" scale="0.001 0.001 0.001"/>
      </geometry>
      <material name="silver"/>
    </visual>
    <collision>
      <origin rpy="0 0 0" xyz="-0.163824 -0.056556 -0.545234"/>
      <geometry>
        <mesh filename="package://abi_description/meshes/l_hip_pitch_link__1__1.stl" scale="0.001 0.001 0.001"/>
      </geometry>
    </collision>
  </link>
  <link name="r_hip_pitch_link__1__1">
    <inertial>
      <origin rpy="0 0 0" xyz="0.018635580884218798 0.006566387842180062 -0.15609272532252366"/>
      <mass value="0.24713382283834584"/>
      <inertia ixx="0.001846" ixy="-3e-06" ixz="-7.5e-05" iyy="0.001908" iyz="-6.3e-05" izz="0.000133"/>
    </inertial>
    <visual>
      <origin rpy="0 0 0" xyz="-0.019665 -0.056556 -0.545234"/>
      <geometry>
        <mesh filename="package://abi_description/meshes/r_hip_pitch_link__1__1.stl" scale="0.001 0.001 0.001"/>
      </geometry>
      <material name="silver"/>
    </visual>
    <collision>
      <origin rpy="0 0 0" xyz="-0.019665 -0.056556 -0.545234"/>
      <geometry>
        <mesh filename="package://abi_description/meshes/r_hip_pitch_link__1__1.stl" scale="0.001 0.001 0.001"/>
      </geometry>
    </collision>
  </link>
  <link name="r_knee_pitch_link__1__1">
    <inertial>
      <origin rpy="0 0 0" xyz="0.016591422554264136 0.006747467516479193 -0.11920942018274272"/>
      <mass value="0.17499149080025025"/>
      <inertia ixx="0.000544" ixy="-1e-06" ixz="-2e-05" iyy="0.000575" iyz="-6e-06" izz="6.4e-05"/>
    </inertial>
    <visual>
      <origin rpy="0 0 0" xyz="-0.014615 -0.0599 -0.2868"/>
      <geometry>
        <mesh filename="package://abi_description/meshes/r_knee_pitch_link__1__1.stl" scale="0.001 0.001 0.001"/>
      </geometry>
      <material name="silver"/>
    </visual>
    <collision>
      <origin rpy="0 0 0" xyz="-0.014615 -0.0599 -0.2868"/>
      <geometry>
        <mesh filename="package://abi_description/meshes/r_knee_pitch_link__1__1.stl" scale="0.001 0.001 0.001"/>
      </geometry>
    </collision>
  </link>
  <link name="l_knee_pitch_link__1__1">
    <inertial>
      <origin rpy="0 0 0" xyz="-0.016591246905534235 0.0067700467959229335 -0.11920942018275008"/>
      <mass value="0.17499149080025042"/>
      <inertia ixx="0.000544" ixy="1e-06" ixz="2e-05" iyy="0.000575" iyz="-6e-06" izz="6.4e-05"/>
    </inertial>
    <visual>
      <origin rpy="0 0 0" xyz="-0.215218 -0.0599 -0.2868"/>
      <geometry>
        <mesh filename="package://abi_description/meshes/l_knee_pitch_link__1__1.stl" scale="0.001 0.001 0.001"/>
      </geometry>
      <material name="silver"/>
    </visual>
    <collision>
      <origin rpy="0 0 0" xyz="-0.215218 -0.0599 -0.2868"/>
      <geometry>
        <mesh filename="package://abi_description/meshes/l_knee_pitch_link__1__1.stl" scale="0.001 0.001 0.001"/>
      </geometry>
    </collision>
  </link>
  <link name="r_ankle_pitch_link__1__1">
    <inertial>
      <origin rpy="0 0 0" xyz="0.02148738924453114 2.238487173400472e-14 -0.039819701337625094"/>
      <mass value="0.43867923251173946"/>
      <inertia ixx="0.000382" ixy="0.0" ixz="1.6e-05" iyy="0.00041" iyz="-0.0" izz="0.000239"/>
    </inertial>
    <visual>
      <origin rpy="0 0 0" xyz="-0.009565 -0.0657 -0.111"/>
      <geometry>
        <mesh filename="package://abi_description/meshes/r_ankle_pitch_link__1__1.stl" scale="0.001 0.001 0.001"/>
      </geometry>
      <material name="silver"/>
    </visual>
    <collision>
      <origin rpy="0 0 0" xyz="-0.009565 -0.0657 -0.111"/>
      <geometry>
        <mesh filename="package://abi_description/meshes/r_ankle_pitch_link__1__1.stl" scale="0.001 0.001 0.001"/>
      </geometry>
    </collision>
  </link>
  <link name="l_ankle_pitch_link__1__1">
    <inertial>
      <origin rpy="0 0 0" xyz="-0.021029577352662004 1.1560891133299833e-11 -0.03981971305451969"/>
      <mass value="0.4386795234282766"/>
      <inertia ixx="0.000382" ixy="0.0" ixz="-1e-05" iyy="0.000409" iyz="-0.0" izz="0.000238"/>
    </inertial>
    <visual>
      <origin rpy="0 0 0" xyz="-0.220268 -0.0657 -0.111"/>
      <geometry>
        <mesh filename="package://abi_description/meshes/l_ankle_pitch_link__1__1.stl" scale="0.001 0.001 0.001"/>
      </geometry>
      <material name="silver"/>
    </visual>
    <collision>
      <origin rpy="0 0 0" xyz="-0.220268 -0.0657 -0.111"/>
      <geometry>
        <mesh filename="package://abi_description/meshes/l_ankle_pitch_link__1__1.stl" scale="0.001 0.001 0.001"/>
      </geometry>
    </collision>
  </link>
  <link name="l_ankle_roll_link__1__1">
    <inertial>
      <origin rpy="0 0 0" xyz="0.011716076785898283 0.01990502610878888 -0.01073478983305472"/>
      <mass value="0.10409112257089649"/>
      <inertia ixx="8.4e-05" ixy="0.0" ixz="1e-06" iyy="4.3e-05" iyz="-0.0" izz="8.9e-05"/>
    </inertial>
    <visual>
      <origin rpy="0 0 0" xyz="-0.188973 -0.0452 -0.027"/>
      <geometry>
        <mesh filename="package://abi_description/meshes/l_ankle_roll_link__1__1.stl" scale="0.001 0.001 0.001"/>
      </geometry>
      <material name="silver"/>
    </visual>
    <collision>
      <origin rpy="0 0 0" xyz="-0.188973 -0.0452 -0.027"/>
      <geometry>
        <mesh filename="package://abi_description/meshes/l_ankle_roll_link__1__1.stl" scale="0.001 0.001 0.001"/>
      </geometry>
    </collision>
  </link>
  <link name="r_ankle_roll_link__1__1">
    <inertial>
      <origin rpy="0 0 0" xyz="-0.01171601249972238 0.019905026108781483 -0.010710304141445231"/>
      <mass value="0.10409112257090966"/>
      <inertia ixx="8.4e-05" ixy="-0.0" ixz="-1e-06" iyy="4.3e-05" iyz="-0.0" izz="8.9e-05"/>
    </inertial>
    <visual>
      <origin rpy="0 0 0" xyz="-0.0425 -0.0452 -0.027"/>
      <geometry>
        <mesh filename="package://abi_description/meshes/r_ankle_roll_link__1__1.stl" scale="0.001 0.001 0.001"/>
      </geometry>
      <material name="silver"/>
    </visual>
    <collision>
      <origin rpy="0 0 0" xyz="-0.0425 -0.0452 -0.027"/>
      <geometry>
        <mesh filename="package://abi_description/meshes/r_ankle_roll_link__1__1.stl" scale="0.001 0.001 0.001"/>
      </geometry>
    </collision>
  </link>
  <joint name="r_hip_roll_joint" type="revolute">
    <origin rpy="0 0 0" xyz="0.095665 0.048506 0.588984"/>
    <parent link="base_footprint"/>
    <child link="r_hip_roll_link_1"/>
    <axis xyz="0.0 -1.0 0.0"/>
    <limit effort="100" lower="-0.349066" upper="0.174533" velocity="100"/>
  </joint>
  <joint name="l_hip_roll_joint" type="revolute">
    <origin rpy="0 0 0" xyz="0.134824 0.048506 0.588984"/>
    <parent link="base_footprint"/>
    <child link="l_hip_roll_link__1__1"/>
    <axis xyz="0.0 -1.0 0.0"/>
    <limit effort="100" lower="-0.174533" upper="0.349066" velocity="100"/>
  </joint>
  <joint name="r_hip_yaw_joint" type="revolute">
    <origin rpy="0 0 0" xyz="-0.0525 0.00805 -0.01975"/>
    <parent link="r_hip_roll_link_1"/>
    <child link="r_hip_yaw_link_1"/>
    <axis xyz="-0.0 -0.0 -1.0"/>
    <limit effort="100" lower="-1.570796" upper="1.570796" velocity="100"/>
  </joint>
  <joint name="l_hip_yaw_joint" type="revolute">
    <origin rpy="0 0 0" xyz="0.0525 0.00805 -0.01975"/>
    <parent link="l_hip_roll_link__1__1"/>
    <child link="l_hip_yaw_link_1"/>
    <axis xyz="-0.0 -0.0 -1.0"/>
    <limit effort="100" lower="-1.570796" upper="1.570796" velocity="100"/>
  </joint>
  <joint name="l_hip_pitch_joint" type="continuous">
    <origin rpy="0 0 0" xyz="-0.0235 0.0 -0.024"/>
    <parent link="l_hip_yaw_link_1"/>
    <child link="l_hip_pitch_link__1__1"/>
    <axis xyz="-1.0 -0.0 -0.0"/>
  </joint>
  <joint name="r_hip_pitch_joint" type="continuous">
    <origin rpy="0 0 0" xyz="-0.0235 0.0 -0.024"/>
    <parent link="r_hip_yaw_link_1"/>
    <child link="r_hip_pitch_link__1__1"/>
    <axis xyz="-1.0 -0.0 -0.0"/>
  </joint>
  <joint name="r_knee_pitch_joint" type="revolute">
    <origin rpy="0 0 0" xyz="-0.00505 0.003344 -0.258434"/>
    <parent link="r_hip_pitch_link__1__1"/>
    <child link="r_knee_pitch_link__1__1"/>
    <axis xyz="-1.0 -0.0 -0.0"/>
    <limit effort="100" lower="-1.919862" upper="0.174533" velocity="100"/>
  </joint>
  <joint name="l_knee_pitch_joint" type="revolute">
    <origin rpy="0 0 0" xyz="0.051394 0.003344 -0.258434"/>
    <parent link="l_hip_pitch_link__1__1"/>
    <child link="l_knee_pitch_link__1__1"/>
    <axis xyz="1.0 0.0 0.0"/>
    <limit effort="100" lower="-0.174533" upper="1.919862" velocity="100"/>
  </joint>
  <joint name="r_ankle_pitch_joint" type="revolute">
    <origin rpy="0 0 0" xyz="-0.00505 0.0058 -0.1758"/>
    <parent link="r_knee_pitch_link__1__1"/>
    <child link="r_ankle_pitch_link__1__1"/>
    <axis xyz="-1.0 -0.0 -0.0"/>
    <limit effort="100" lower="-0.785398" upper="0.785398" velocity="100"/>
  </joint>
  <joint name="l_ankle_pitch_joint" type="revolute">
    <origin rpy="0 0 0" xyz="0.00505 0.0058 -0.1758"/>
    <parent link="l_knee_pitch_link__1__1"/>
    <child link="l_ankle_pitch_link__1__1"/>
    <axis xyz="1.0 -0.0 0.0"/>
    <limit effort="100" lower="-0.785398" upper="0.785398" velocity="100"/>
  </joint>
  <joint name="l_ankle_roll_joint" type="revolute">
    <origin rpy="0 0 0" xyz="-0.031295 -0.0205 -0.084"/>
    <parent link="l_ankle_pitch_link__1__1"/>
    <child link="l_ankle_roll_link__1__1"/>
    <axis xyz="-0.0 1.0 -0.0"/>
    <limit effort="100" lower="-0.174533" upper="0.785398" velocity="100"/>
  </joint>
  <joint name="r_ankle_roll_joint" type="revolute">
    <origin rpy="0 0 0" xyz="0.032935 -0.0205 -0.084"/>
    <parent link="r_ankle_pitch_link__1__1"/>
    <child link="r_ankle_roll_link__1__1"/>
    <axis xyz="-0.0 1.0 -0.0"/>
    <limit effort="100" lower="-0.785398" upper="0.174533" velocity="100"/>
  </joint>
</robot>

